Workbook

Sheet JANUARI 26
A1: DATA RINCIAN PENDAPATAN E-TICKETING NEW GATE BULAN JANUARI 2026
A3: NO | B3: JENIS PENDAPATAN | C3: TANGGAL | AH3: JUMLAH | AM3: PENDAPATAN
C4: 1 | D4: 2 | E4: 3 | F4: 4 | G4: 5 | H4: 6 | I4: 7 | J4: 8 | K4: 9 | L4: 10 | M4: 11 | N4: 12 | O4: 13 | P4: 14 | Q4: 15 | R4: 16 | S4: 17 | T4: 18 | U4: 19 | V4: 20 | W4: 21 | X4: 22 | Y4: 23 | Z4: 24 | AA4: 25 | AB4: 26 | AC4: 27 | AD4: 28 | AE4: 29 | AF4: 30 | AG4: 31 | AM4: TAMAN MARGASATWA RAGUNAN 2018 :
A5: 1 | B5: Dewasa | C5: 107284000 | D5: 11396000 | E5: 40336000 | F5: 47272000 | H5: 16256000 | I5: 12688000 | J5: 12724000 | K5: 7912000 | L5: 28672000 | M5: 24328000 | O5: 3904000 | P5: 2456000 | Q5: 2980000 | R5: 21600000 | S5: 20612000 | T5: 14740000 | V5: 3720000 | W5: 1516000 | X5: 4900000 | Y5: 648000 | Z5: 5656000 | AA5: 18236000 | AC5: 3812000 | AD5: 3292000 | AE5: 1124000 | AF5: 2032000 | AG5: 11144000 | AH5: =SUM(C5:AG5) -> 431240000 | AI5: =AH5/4000 -> 107810 | AJ5: 180664000 | AK5: =AH5+AJ5 -> 611904000 | AM5: Dewasa | AN5: =AH5 -> 431240000
A6: 2 | B6: Anak | C6: 32190000 | D6: 3270000 | E6: 11874000 | F6: 13116000 | H6: 5001000 | I6: 3504000 | J6: 3672000 | K6: 1974000 | L6: 7290000 | M6: 5511000 | O6: 564000 | P6: 294000 | Q6: 399000 | R6: 4179000 | S6: 4497000 | T6: 3168000 | V6: 459000 | W6: 198000 | X6: 408000 | Y6: 111000 | Z6: 846000 | AA6: 3693000 | AC6: 504000 | AD6: 360000 | AE6: 123000 | AF6: 207000 | AG6: 2022000 | AH6: =SUM(C6:AG6) -> 109434000 | AI6: =AH6/3000 -> 36478 | AJ6: 33786000 | AK6: =AH6+AJ6 -> 143220000 | AM6: Anak | AN6: =AH6 -> 109434000
A7: 3 | B7: Rombongan Dewasa | AH7: =SUM(C7:AG7) -> 0 | AI7: =AH7/3000 -> 0 | AK7: =AH7+AJ7 -> 0 | AM7: Rombongan Dewasa | AN7: =AH7 -> 0
A8: 4 | B8: Rombongan Anak | AH8: =SUM(C8:AG8) -> 0 | AI8: =AH8/2250 -> 0 | AK8: =AH8+AJ8 -> 0 | AM8: Rombongan Anak | AN8: =AH8 -> 0
A9: 5 | B9: Taman Satwa Anak | C9: 3047500 | D9: 445000 | E9: 687500 | F9: 1157500 | H9: 165000 | I9: 117500 | J9: 110000 | K9: 40000 | L9: 1087500 | M9: 662500 | O9: 92500 | P9: 17500 | Q9: 57500 | R9: 417500 | S9: 290000 | T9: 392500 | V9: 62500 | W9: 17500 | X9: 10000 | Z9: 30000 | AA9: 380000 | AC9: 17500 | AD9: 47500 | AF9: 25000 | AG9: 322500 | AH9: =SUM(C9:AG9) -> 9700000 | AI9: =AH9/2500 -> 3880 | AJ9: 19400000 | AK9: =AH9+AJ9 -> 29100000
A10: 6 | B10: PPS Hari Selasa-Jum'at Dewasa | D10: 5976000 | H10: 3288000 | I10: 2694000 | J10: 2322000 | K10: 996000 | O10: 498000 | P10: 300000 | Q10: 390000 | V10: 738000 | W10: 390000 | X10: 216000 | Y10: 66000 | AC10: 558000 | AD10: 462000 | AE10: 342000 | AF10: 264000 | AH10: =SUM(C10:AG10) -> 19500000 | AI10: =AH10/6000 -> 3250 | AJ10: 22992000 | AK10: =AH10+AJ10 -> 42492000 | AM10: Sepeda | AN10: =AH10 -> 19500000
A11: 7 | B11: PPS Hari Selasa-Jum'at Anak | D11: 5448000 | H11: 1590000 | I11: 1248000 | J11: 1572000 | K11: 738000 | O11: 306000 | P11: 36000 | Q11: 96000 | V11: 150000 | W11: 30000 | X11: 30000 | Y11: 12000 | AC11: =6000+48000 -> 54000 | AD11: 84000 | AE11: 12000 | AF11: 18000 | AH11: =SUM(C11:AG11) -> 11424000 | AI11: =AH11/6000 -> 1904 | AJ11: 6276000 | AK11: =AH11+AJ11 -> 17700000 | AM11: Kuda Tunggang | AN11: =AH11 -> 11424000
A12: 8 | B12: Romb PPS Hari Selasa-Jum'at Dewasa | AH12: =SUM(C12:AG12) -> 0 | AI12: =AH12/4500 -> 0 | AK12: =AH12+AJ12 -> 0 | AM12: Unta Tunggang | AN12: =AH12 -> 0
A13: 9 | B13: Romb PPS Hari Selasa-Jum'at Anak | AH13: =SUM(C13:AG13) -> 0 | AI13: =AH13/4500 -> 0 | AK13: =AH13+AJ13 -> 0 | AM13: Gajah Tunggang | AN13: =AH13 -> 0
A14: 10 | B14: PPS Hari Sabtu-Minggu/Libur Nasional Dewasa | C14: 21667500 | E14: 11415000 | F14: 11962500 | L14: 9180000 | M14: 8947500 | R14: 7012500 | S14: 7215000 | T14: 4005000 | Z14: 1530000 | AA14: 5190000 | AG14: 2880000 | AH14: =SUM(C14:AG14) -> 91005000 | AI14: =AH14/7500 -> 12134 | AJ14: 74100000 | AK14: =AH14+AJ14 -> 165105000 | AM14: Taman Satwa Anak / Pentas | AN14: =AH14 -> 91005000
A15: 11 | B15: PPS Hari Sabtu-Minggu/Libur Nasional Anak | C15: 17970000 | E15: 8662500 | F15: 15975000 | L15: 7380000 | M15: 7395000 | R15: 5355000 | S15: 5542500 | T15: 2700000 | Z15: 1005000 | AA15: 4110000 | AG15: 1972500 | AH15: =SUM(C15:AG15) -> 78067500 | AI15: =AH15/7500 -> 10409 | AJ15: 17302500 | AK15: =AH15+AJ15 -> 95370000 | AM15: PPS Hari Selasa-Jum'at Dewasa | AN15: =AH15 -> 78067500
A16: 12 | B16: Romb PPS Hari Sabtu-Minggu/Libur Nasional Dewasa | AH16: =SUM(C16:AG16) -> 0 | AI16: =AH16/5625 -> 0 | AK16: =AH16+AJ16 -> 0 | AM16: PPS Hari Selasa-Jum'at Anak | AN16: =AH16 -> 0
A17: 13 | B17: Romb PPS Hari Sabtu-Minggu/Libur Nasional Anak | AH17: =SUM(C17:AG17) -> 0 | AI17: =AH17/5625 -> 0 | AK17: =AH17+AJ17 -> 0 | AM17: Romb PPS Hari Selasa-Jum'at Dewasa | AN17: =AH17 -> 0
A18: 14 | B18: Kendaraan Golongan I | AH18: =SUM(C18:AG18) -> 0 | AI18: =AH18/15000 -> 0 | AJ18: 1080000 | AK18: =AH18+AJ18 -> 1080000 | AM18: Romb PPS Hari Selasa-Jum'at Anak | AN18: =AH18 -> 0
A19: 15 | B19: Kendaraan Golongan II | AH19: =SUM(C19:AG19) -> 0 | AI19: =AH19/12500 -> 0 | AJ19: 850000 | AK19: =AH19+AJ19 -> 850000 | AM19: PPS Hari Sabtu-Minggu/Libur Nasional Dewasa | AN19: =AH19 -> 0
A20: 16 | B20: Kendaraan Golongan III | AH20: =SUM(C20:AG20) -> 0 | AI20: =AH20/6000 -> 0 | AJ20: 16146000 | AK20: =AH20+AJ20 -> 16146000 | AM20: PPS Hari Sabtu-Minggu/Libur Nasional Anak | AN20: =AH20 -> 0
A21: 17 | B21: Sepeda Motor | AH21: =SUM(C21:AG21) -> 0 | AI21: =AH21/3000 -> 0 | AJ21: 12579000 | AK21: =AH21+AJ21 -> 12579000 | AM21: Romb PPS Hari Sabtu-Minggu/Libur Nasional Dewasa | AN21: =AH21 -> 0
A22: 18 | B22: Sepeda | AH22: =SUM(C22:AG22) -> 0 | AI22: =AH22/1000 -> 0 | AJ22: 801000 | AK22: =AH22+AJ22 -> 801000 | AM22: Romb PPS Hari Sabtu-Minggu/Libur Nasional Anak | AN22: =AH22 -> 0
B23: Jumlah | C23: =SUM(C5:C22) -> 182159000 | D23: =SUM(D5:D22) -> 26535000 | E23: =SUM(E5:E22) -> 72975000 | F23: =SUM(F5:F22) -> 89483000 | G23: =SUM(G5:G22) -> 0 | H23: =SUM(H5:H22) -> 26300000 | I23: =SUM(I5:I22) -> 20251500 | J23: =SUM(J5:J22) -> 20400000 | ... AH23: =SUM(AH5:AH22) -> 750370500 | AJ23: =SUM(AJ5:AJ22) -> 385976500 | AM23: Jumlah | AN23: =AH23 -> 750370500
B27: PENGUNJUNG | AM27: ASURANSI LEMBAR
B28: T A N G G A L | C28: 1 | D28: 2 | E28: 3 | F28: 4 | G28: 5 | H28: 6 | I28: 7 | J28: 8 | K28: 9 | L28: 10 | M28: 11 | N28: 12 | O28: 13 | P28: 14 | Q28: 15 | R28: 16 | S28: 17 | T28: 18 | U28: 19 | V28: 20 | W28: 21 | X28: 22 | Y28: 23 | Z28: 24 | AA28: 25 | AB28: 26 | AC28: 27 | AD28: 28 | AE28: 29 | AF28: 30 | AG28: 31 | AH28: jumlah | AM28: T A N G G A L
B29: Dewasa | C29: =C5/4000 -> 26821 | D29: =D5/4000 -> 2849 | E29: =E5/4000 -> 10084 | F29: =F5/4000 -> 11818 | G29: =G5/4000 -> 0 | H29: =H5/4000 -> 4064 | I29: =I5/4000 -> 3172 | J29: =J5/4000 -> 3181 | ... AG29: =AG5/4000 -> 2786 | AH29: =SUM(C29:AG29) -> 107810 | AM29: Dewasa | AN29: =AH29 -> 107810
B30: Anak | C30: =C6/3000 -> 10730 | D30: =D6/3000 -> 1090 | E30: =E6/3000 -> 3958 | F30: =F6/3000 -> 4372 | G30: =G6/3000 -> 0 | H30: =H6/3000 -> 1667 | I30: =I6/3000 -> 1168 | J30: =J6/3000 -> 1224 | ... AG30: =AG6/3000 -> 674 | AH30: =SUM(C30:AG30) -> 36478 | AM30: Anak | AN30: =AH30 -> 36478
B31: Rombongan Dewasa | C31: =C7/3000 -> 0 | D31: =D7/3000 -> 0 | E31: =E7/3000 -> 0 | F31: =F7/3000 -> 0 | G31: =G7/3000 -> 0 | H31: =H7/3000 -> 0 | I31: =I7/3000 -> 0 | J31: =J7/3000 -> 0 | ... AG31: =AG7/3000 -> 0 | AH31: =SUM(C31:AG31) -> 0 | AM31: Rombongan Dewasa | AN31: =AH31 -> 0
B32: Rombongan Anak | C32: =C8/2250 -> 0 | D32: =D8/2250 -> 0 | E32: =E8/2250 -> 0 | F32: =F8/2250 -> 0 | G32: =G8/2250 -> 0 | H32: =H8/2250 -> 0 | I32: =I8/2250 -> 0 | J32: =J8/2250 -> 0 | ... AG32: =AG8/2250 -> 0 | AH32: =SUM(C32:AG32) -> 0 | AM32: Rombongan Anak | AN32: =AH32 -> 0
B33: Taman Satwa Anak | C33: =C9/2500 -> 1219 | D33: =D9/2500 -> 178 | E33: =E9/2500 -> 275 | F33: =F9/2500 -> 463 | G33: =G9/2500 -> 0 | H33: =H9/2500 -> 66 | I33: =I9/2500 -> 47 | J33: =J9/2500 -> 44 | ... AG33: =AG9/2500 -> 129 | AH33: =SUM(C33:AG33) -> 3880
B34: PPS Hari Selasa-Jum'at Dewasa | C34: =C10/6000 -> 0 | D34: =D10/6000 -> 996 | E34: =E10/6000 -> 0 | F34: =F10/6000 -> 0 | G34: =G10/6000 -> 0 | H34: =H10/6000 -> 548 | I34: =I10/6000 -> 449 | J34: =J10/6000 -> 387 | ... AG34: =AG10/6000 -> 0 | AH34: =SUM(C34:AG34) -> 3250 | AM34: Sepeda | AN34: =AH34 -> 3250
B35: PPS Hari Selasa-Jum'at Anak | C35: =C11/6000 -> 0 | D35: =D11/6000 -> 908 | E35: =E11/6000 -> 0 | F35: =F11/6000 -> 0 | G35: =G11/6000 -> 0 | H35: =H11/6000 -> 265 | I35: =I11/6000 -> 208 | J35: =J11/6000 -> 262 | ... AG35: =AG11/6000 -> 0 | AH35: =SUM(C35:AG35) -> 1904 | AM35: JUMLAH Rp | AN35: =AH35 -> 1904
B36: Romb PPS Hari Selasa-Jum'at Dewasa | C36: =C12/4500 -> 0 | D36: =D12/4500 -> 0 | E36: =E12/4500 -> 0 | F36: =F12/4500 -> 0 | G36: =G12/4500 -> 0 | H36: =H12/4500 -> 0 | I36: =I12/4500 -> 0 | J36: =J12/4500 -> 0 | ... AG36: =AG12/4500 -> 0 | AH36: =SUM(C36:AG36) -> 0 | AM36: PPS Dewasa | AN36: =AH36 -> 0
B37: Romb PPS Hari Selasa-Jum'at Anak | C37: =C13/4500 -> 0 | D37: =D13/4500 -> 0 | E37: =E13/4500 -> 0 | F37: =F13/4500 -> 0 | G37: =G13/4500 -> 0 | H37: =H13/4500 -> 0 | I37: =I13/4500 -> 0 | J37: =J13/4500 -> 0 | ... AG37: =AG13/4500 -> 0 | AH37: =SUM(C37:AG37) -> 0 | AM37: PPS Anak | AN37: =AH37 -> 0
B38: PPS Hari Sabtu-Minggu/Libur Nasional Dewasa | C38: =C14/7500 -> 2889 | D38: =D14/7500 -> 0 | E38: =E14/7500 -> 1522 | F38: =F14/7500 -> 1595 | G38: =G14/7500 -> 0 | H38: =H14/7500 -> 0 | I38: =I14/7500 -> 0 | J38: =J14/7500 -> 0 | ... AG38: =AG14/7500 -> 384 | AH38: =SUM(C38:AG38) -> 12134 | AM38: PPS Romb.Dewasa | AN38: =AH38 -> 12134
B39: PPS Hari Sabtu-Minggu/Libur Nasional Anak | C39: =C15/7500 -> 2396 | D39: =D15/7500 -> 0 | E39: =E15/7500 -> 1155 | F39: =F15/7500 -> 2130 | G39: =G15/7500 -> 0 | H39: =H15/7500 -> 0 | I39: =I15/7500 -> 0 | J39: =J15/7500 -> 0 | ... AG39: =AG15/7500 -> 263 | AH39: =SUM(C39:AG39) -> 10409 | AM39: PPS Romb. Anak | AN39: =AH39 -> 10409
B40: Romb PPS Hari Sabtu-Minggu/Libur Nasional Dewasa | C40: =C16/5625 -> 0 | D40: =D16/5625 -> 0 | E40: =E16/5625 -> 0 | F40: =F16/5625 -> 0 | G40: =G16/5625 -> 0 | H40: =H16/5625 -> 0 | I40: =I16/5625 -> 0 | J40: =J16/5625 -> 0 | ... AG40: =AG16/5625 -> 0 | AH40: =SUM(C40:AG40) -> 0 | AM40: JUMLAH Rp | AN40: =AH40 -> 0
B41: Romb PPS Hari Sabtu-Minggu/Libur Nasional Anak | C41: =C17/5625 -> 0 | D41: =D17/5625 -> 0 | E41: =E17/5625 -> 0 | F41: =F17/5625 -> 0 | G41: =G17/5625 -> 0 | H41: =H17/5625 -> 0 | I41: =I17/5625 -> 0 | J41: =J17/5625 -> 0 | ... AG41: =AG17/5625 -> 0 | AH41: =SUM(C41:AG41) -> 0
B42: Kendaraan Golongan I | C42: =C18/15000 -> 0 | D42: =D18/15000 -> 0 | E42: =E18/15000 -> 0 | F42: =F18/15000 -> 0 | G42: =G18/15000 -> 0 | H42: =H18/15000 -> 0 | I42: =I18/15000 -> 0 | J42: =J18/15000 -> 0 | ... AG42: =AG18/15000 -> 0 | AH42: =SUM(C42:AG42) -> 0
B43: Kendaraan Golongan II | C43: =C19/12500 -> 0 | D43: =D19/12500 -> 0 | E43: =E19/12500 -> 0 | F43: =F19/12500 -> 0 | G43: =G19/12500 -> 0 | H43: =H19/12500 -> 0 | I43: =I19/12500 -> 0 | J43: =J19/12500 -> 0 | ... AG43: =AG19/12500 -> 0 | AH43: =SUM(C43:AG43) -> 0
B44: Kendaraan Golongan III | C44: =C20/6000 -> 0 | D44: =D20/6000 -> 0 | E44: =E20/6000 -> 0 | F44: =F20/6000 -> 0 | G44: =G20/6000 -> 0 | H44: =H20/6000 -> 0 | I44: =I20/6000 -> 0 | J44: =J20/6000 -> 0 | ... AG44: =AG20/6000 -> 0 | AH44: =SUM(C44:AG44) -> 0
...

Sheet Februari 26
A1: DATA RINCIAN PENDAPATAN E-TICKETING NEW GATE BULAN JANUARI 2026
A3: NO | B3: JENIS PENDAPATAN | C3: TANGGAL | AE3: JUMLAH | AJ3: PENDAPATAN
C4: 1 | D4: 2 | E4: 3 | F4: 4 | G4: 5 | H4: 6 | I4: 7 | J4: 8 | K4: 9 | L4: 10 | M4: 11 | N4: 12 | O4: 13 | P4: 14 | Q4: 15 | R4: 16 | S4: 17 | T4: 18 | U4: 19 | V4: 20 | W4: 21 | X4: 22 | Y4: 23 | Z4: 24 | AA4: 25 | AB4: 26 | AC4: 27 | AD4: 28 | AJ4: TAMAN MARGASATWA RAGUNAN 2018 :
A5: 1 | B5: Dewasa | C5: 19460000 | E5: 6380000 | F5: 4032000 | G5: 4836000 | H5: 3144000 | I5: 14660000 | J5: 17828000 | L5: 5068000 | M5: 5236000 | N5: 4736000 | O5: 3160000 | P5: 15004000 | Q5: 26532000 | R5: 6596000 | S5: 21700000 | U5: 744000 | V5: 896000 | W5: 2484000 | X5: 2096000 | Z5: 1020000 | AA5: 936000 | AB5: 1028000 | AC5: 736000 | AD5: 2980000 | AE5: =SUM(C5:AD5) -> 171292000 | AF5: =AE5/4000 -> 42823 | AG5: 81424000 | AH5: =AE5+AG5 -> 252716000 | AJ5: Dewasa | AK5: =AE5 -> 171292000
A6: 2 | B6: Anak | C6: 3723000 | E6: 801000 | F6: 396000 | G6: 723000 | H6: 357000 | I6: 2712000 | J6: 3957000 | L6: 603000 | M6: 735000 | N6: 696000 | O6: 432000 | P6: 2742000 | Q6: 5373000 | R6: 1512000 | S6: 4539000 | U6: 168000 | V6: 153000 | W6: 438000 | X6: 411000 | Z6: 138000 | AA6: 99000 | AB6: 150000 | AC6: 78000 | AD6: 429000 | AE6: =SUM(C6:AD6) -> 31365000 | AF6: =AE6/3000 -> 10455 | AG6: 10629000 | AH6: =AE6+AG6 -> 41994000 | AJ6: Anak | AK6: =AE6 -> 31365000
A7: 3 | B7: Rombongan Dewasa | AE7: =SUM(C7:AD7) -> 0 | AF7: =AE7/3000 -> 0 | AH7: =AE7+AG7 -> 0 | AJ7: Rombongan Dewasa | AK7: =AE7 -> 0
A8: 4 | B8: Rombongan Anak | AE8: =SUM(C8:AD8) -> 0 | AF8: =AE8/2250 -> 0 | AH8: =AE8+AG8 -> 0 | AJ8: Rombongan Anak | AK8: =AE8 -> 0
A9: 5 | B9: Taman Satwa Anak | C9: 552500 | E9: 10000 | F9: 25000 | G9: 37500 | H9: 12500 | I9: 432500 | J9: 355000 | L9: 5000 | M9: 7500 | N9: 62500 | O9: 42500 | P9: 347500 | Q9: 822500 | R9: 40000 | S9: 672500 | U9: 2500 | V9: 20000 | Z9: 15000 | AA9: 15000 | AD9: 17500 | AE9: =SUM(C9:AD9) -> 3495000 | AF9: =AE9/2500 -> 1398 | AG9: 8072500 | AH9: =AE9+AG9 -> 11567500
A10: 6 | B10: PPS Hari Selasa-Jum'at Dewasa | E10: 600000 | F10: 342000 | G10: 330000 | H10: 330000 | L10: 264000 | M10: 624000 | N10: 258000 | O10: 168000 | U10: 18000 | V10: 18000 | Z10: 18000 | AA10: 48000 | AB10: 54000 | AC10: 36000 | AE10: =SUM(C10:AD10) -> 3108000 | AF10: =AE10/6000 -> 518 | AG10: 9930000 | AH10: =AE10+AG10 -> 13038000 | AJ10: Sepeda | AK10: =AE10 -> 3108000
A11: 7 | B11: PPS Hari Selasa-Jum'at Anak | E11: 210000 | F11: 228000 | G11: 108000 | H11: 234000 | L11: 156000 | M11: 288000 | N11: 186000 | O11: 174000 | U11: 36000 | V11: 18000 | Z11: 42000 | AA11: 36000 | AB11: 30000 | AC11: 42000 | AE11: =SUM(C11:AD11) -> 1788000 | AF11: =AE11/6000 -> 298 | AG11: 1896000 | AH11: =AE11+AG11 -> 3684000 | AJ11: Kuda Tunggang | AK11: =AE11 -> 1788000
A12: 8 | B12: Romb PPS Hari Selasa-Jum'at Dewasa | AE12: =SUM(C12:AD12) -> 0 | AF12: =AE12/4500 -> 0 | AH12: =AE12+AG12 -> 0 | AJ12: Unta Tunggang | AK12: =AE12 -> 0
A13: 9 | B13: Romb PPS Hari Selasa-Jum'at Anak | AE13: =SUM(C13:AD13) -> 0 | AF13: =AE13/4500 -> 0 | AH13: =AE13+AG13 -> 0 | AJ13: Gajah Tunggang | AK13: =AE13 -> 0
A14: 10 | B14: PPS Hari Sabtu-Minggu/Libur Nasional Dewasa | C14: 5280000 | I14: 3900000 | J14: 4312500 | P14: 4140000 | Q14: 8482500 | R14: 2220000 | S14: 7665000 | W14: 172500 | X14: 45000 | AD14: 90000 | AE14: =SUM(C14:AD14) -> 36307500 | AF14: =AE14/7500 -> 4841 | AG14: 37672500 | AH14: =AE14+AG14 -> 73980000 | AJ14: Taman Satwa Anak / Pentas | AK14: =AE14 -> 36307500
A15: 11 | B15: PPS Hari Sabtu-Minggu/Libur Nasional Anak | C15: 4200000 | I15: 2805000 | J15: 2842500 | P15: 3225000 | Q15: 7447500 | R15: 1807500 | S15: 6210000 | W15: 195000 | X15: 75000 | AD15: 135000 | AE15: =SUM(C15:AD15) -> 28942500 | AF15: =AE15/7500 -> 3859 | AG15: 7065000 | AH15: =AE15+AG15 -> 36007500 | AJ15: PPS Hari Selasa-Jum'at Dewasa | AK15: =AE15 -> 28942500
A16: 12 | B16: Romb PPS Hari Sabtu-Minggu/Libur Nasional Dewasa | AE16: =SUM(C16:AD16) -> 0 | AF16: =AE16/5625 -> 0 | AH16: =AE16+AG16 -> 0 | AJ16: PPS Hari Selasa-Jum'at Anak | AK16: =AE16 -> 0
A17: 13 | B17: Romb PPS Hari Sabtu-Minggu/Libur Nasional Anak | AE17: =SUM(C17:AD17) -> 0 | AF17: =AE17/5625 -> 0 | AH17: =AE17+AG17 -> 0 | AJ17: Romb PPS Hari Selasa-Jum'at Dewasa | AK17: =AE17 -> 0
A18: 14 | B18: Kendaraan Golongan I | AE18: =SUM(C18:AD18) -> 0 | AF18: =AE18/15000 -> 0 | AG18: 750000 | AH18: =AE18+AG18 -> 750000 | AJ18: Romb PPS Hari Selasa-Jum'at Anak | AK18: =AE18 -> 0
A19: 15 | B19: Kendaraan Golongan II | AE19: =SUM(C19:AD19) -> 0 | AF19: =AE19/12500 -> 0 | AG19: 275000 | AH19: =AE19+AG19 -> 275000 | AJ19: PPS Hari Sabtu-Minggu/Libur Nasional Dewasa | AK19: =AE19 -> 0
A20: 16 | B20: Kendaraan Golongan III | AE20: =SUM(C20:AD20) -> 0 | AF20: =AE20/6000 -> 0 | AG20: 7014000 | AH20: =AE20+AG20 -> 7014000 | AJ20: PPS Hari Sabtu-Minggu/Libur Nasional Anak | AK20: =AE20 -> 0
A21: 17 | B21: Sepeda Motor | AE21: =SUM(C21:AD21) -> 0 | AF21: =AE21/3000 -> 0 | AG21: 7149000 | AH21: =AE21+AG21 -> 7149000 | AJ21: Romb PPS Hari Sabtu-Minggu/Libur Nasional Dewasa | AK21: =AE21 -> 0
A22: 18 | B22: Sepeda | AE22: =SUM(C22:AD22) -> 0 | AF22: =AE22/1000 -> 0 | AG22: 428000 | AH22: =AE22+AG22 -> 428000 | AJ22: Romb PPS Hari Sabtu-Minggu/Libur Nasional Anak | AK22: =AE22 -> 0
B23: Jumlah | C23: =SUM(C5:C22) -> 33215500 | D23: =SUM(D5:D22) -> 0 | E23: =SUM(E5:E22) -> 8001000 | F23: =SUM(F5:F22) -> 5023000 | G23: =SUM(G5:G22) -> 6034500 | H23: =SUM(H5:H22) -> 4077500 | I23: =SUM(I5:I22) -> 24509500 | J23: =SUM(J5:J22) -> 29295000 | ... AE23: =SUM(AE5:AE22) -> 276298000 | AG23: =SUM(AG5:AG22) -> 172305000 | AJ23: Jumlah | AK23: =AE23 -> 276298000
B27: PENGUNJUNG | AJ27: ASURANSI LEMBAR
B28: T A N G G A L | C28: 1 | D28: 2 | E28: 3 | F28: 4 | G28: 5 | H28: 6 | I28: 7 | J28: 8 | K28: 9 | L28: 10 | M28: 11 | N28: 12 | O28: 13 | P28: 14 | Q28: 15 | R28: 16 | S28: 17 | T28: 18 | U28: 19 | V28: 20 | W28: 21 | X28: 22 | Y28: 23 | Z28: 24 | AA28: 25 | AB28: 26 | AC28: 27 | AD28: 28 | AE28: jumlah | AJ28: T A N G G A L
B29: Dewasa | C29: =C5/4000 -> 4865 | D29: =D5/4000 -> 0 | E29: =E5/4000 -> 1595 | F29: =F5/4000 -> 1008 | G29: =G5/4000 -> 1209 | H29: =H5/4000 -> 786 | I29: =I5/4000 -> 3665 | J29: =J5/4000 -> 4457 | ... AD29: =AD5/4000 -> 745 | AE29: =SUM(C29:AD29) -> 42823 | AJ29: Dewasa | AK29: =AE29 -> 42823
B30: Anak | C30: =C6/3000 -> 1241 | D30: =D6/3000 -> 0 | E30: =E6/3000 -> 267 | F30: =F6/3000 -> 132 | G30: =G6/3000 -> 241 | H30: =H6/3000 -> 119 | I30: =I6/3000 -> 904 | J30: =J6/3000 -> 1319 | ... AD30: =AD6/3000 -> 143 | AE30: =SUM(C30:AD30) -> 10455 | AJ30: Anak | AK30: =AE30 -> 10455
B31: Rombongan Dewasa | C31: =C7/3000 -> 0 | D31: =D7/3000 -> 0 | E31: =E7/3000 -> 0 | F31: =F7/3000 -> 0 | G31: =G7/3000 -> 0 | H31: =H7/3000 -> 0 | I31: =I7/3000 -> 0 | J31: =J7/3000 -> 0 | ... AD31: =AD7/3000 -> 0 | AE31: =SUM(C31:AD31) -> 0 | AJ31: Rombongan Dewasa | AK31: =AE31 -> 0
B32: Rombongan Anak | C32: =C8/2250 -> 0 | D32: =D8/2250 -> 0 | E32: =E8/2250 -> 0 | F32: =F8/2250 -> 0 | G32: =G8/2250 -> 0 | H32: =H8/2250 -> 0 | I32: =I8/2250 -> 0 | J32: =J8/2250 -> 0 | ... AD32: =AD8/2250 -> 0 | AE32: =SUM(C32:AD32) -> 0 | AJ32: Rombongan Anak | AK32: =AE32 -> 0
B33: Taman Satwa Anak | C33: =C9/2500 -> 221 | D33: =D9/2500 -> 0 | E33: =E9/2500 -> 4 | F33: =F9/2500 -> 10 | G33: =G9/2500 -> 15 | H33: =H9/2500 -> 5 | I33: =I9/2500 -> 173 | J33: =J9/2500 -> 142 | ... AD33: =AD9/2500 -> 7 | AE33: =SUM(C33:AD33) -> 1398
B34: PPS Hari Selasa-Jum'at Dewasa | C34: =C10/6000 -> 0 | D34: =D10/6000 -> 0 | E34: =E10/6000 -> 100 | F34: =F10/6000 -> 57 | G34: =G10/6000 -> 55 | H34: =H10/6000 -> 55 | I34: =I10/6000 -> 0 | J34: =J10/6000 -> 0 | ... AD34: =AD10/6000 -> 0 | AE34: =SUM(C34:AD34) -> 518 | AJ34: Sepeda | AK34: =AE34 -> 518
B35: PPS Hari Selasa-Jum'at Anak | C35: =C11/6000 -> 0 | D35: =D11/6000 -> 0 | E35: =E11/6000 -> 35 | F35: =F11/6000 -> 38 | G35: =G11/6000 -> 18 | H35: =H11/6000 -> 39 | I35: =I11/6000 -> 0 | J35: =J11/6000 -> 0 | ... AD35: =AD11/6000 -> 0 | AE35: =SUM(C35:AD35) -> 298 | AJ35: JUMLAH Rp | AK35: =AE35 -> 298
B36: Romb PPS Hari Selasa-Jum'at Dewasa | C36: =C12/4500 -> 0 | D36: =D12/4500 -> 0 | E36: =E12/4500 -> 0 | F36: =F12/4500 -> 0 | G36: =G12/4500 -> 0 | H36: =H12/4500 -> 0 | I36: =I12/4500 -> 0 | J36: =J12/4500 -> 0 | ... AD36: =AD12/4500 -> 0 | AE36: =SUM(C36:AD36) -> 0 | AJ36: PPS Dewasa | AK36: =AE36 -> 0
B37: Romb PPS Hari Selasa-Jum'at Anak | C37: =C13/4500 -> 0 | D37: =D13/4500 -> 0 | E37: =E13/4500 -> 0 | F37: =F13/4500 -> 0 | G37: =G13/4500 -> 0 | H37: =H13/4500 -> 0 | I37: =I13/4500 -> 0 | J37: =J13/4500 -> 0 | ... AD37: =AD13/4500 -> 0 | AE37: =SUM(C37:AD37) -> 0 | AJ37: PPS Anak | AK37: =AE37 -> 0
B38: PPS Hari Sabtu-Minggu/Libur Nasional Dewasa | C38: =C14/7500 -> 704 | D38: =D14/7500 -> 0 | E38: =E14/7500 -> 0 | F38: =F14/7500 -> 0 | G38: =G14/7500 -> 0 | H38: =H14/7500 -> 0 | I38: =I14/7500 -> 520 | J38: =J14/7500 -> 575 | ... AD38: =AD14/7500 -> 12 | AE38: =SUM(C38:AD38) -> 4841 | AJ38: PPS Romb.Dewasa | AK38: =AE38 -> 4841
B39: PPS Hari Sabtu-Minggu/Libur Nasional Anak | C39: =C15/7500 -> 560 | D39: =D15/7500 -> 0 | E39: =E15/7500 -> 0 | F39: =F15/7500 -> 0 | G39: =G15/7500 -> 0 | H39: =H15/7500 -> 0 | I39: =I15/7500 -> 374 | J39: =J15/7500 -> 379 | ... AD39: =AD15/7500 -> 18 | AE39: =SUM(C39:AD39) -> 3859 | AJ39: PPS Romb. Anak | AK39: =AE39 -> 3859
B40: Romb PPS Hari Sabtu-Minggu/Libur Nasional Dewasa | C40: =C16/5625 -> 0 | D40: =D16/5625 -> 0 | E40: =E16/5625 -> 0 | F40: =F16/5625 -> 0 | G40: =G16/5625 -> 0 | H40: =H16/5625 -> 0 | I40: =I16/5625 -> 0 | J40: =J16/5625 -> 0 | ... AD40: =AD16/5625 -> 0 | AE40: =SUM(C40:AD40) -> 0 | AJ40: JUMLAH Rp | AK40: =AE40 -> 0
B41: Romb PPS Hari Sabtu-Minggu/Libur Nasional Anak | C41: =C17/5625 -> 0 | D41: =D17/5625 -> 0 | E41: =E17/5625 -> 0 | F41: =F17/5625 -> 0 | G41: =G17/5625 -> 0 | H41: =H17/5625 -> 0 | I41: =I17/5625 -> 0 | J41: =J17/5625 -> 0 | ... AD41: =AD17/5625 -> 0 | AE41: =SUM(C41:AD41) -> 0
B42: Kendaraan Golongan I | C42: =C18/15000 -> 0 | D42: =D18/15000 -> 0 | E42: =E18/15000 -> 0 | F42: =F18/15000 -> 0 | G42: =G18/15000 -> 0 | H42: =H18/15000 -> 0 | I42: =I18/15000 -> 0 | J42: =J18/15000 -> 0 | ... AD42: =AD18/15000 -> 0 | AE42: =SUM(C42:AD42) -> 0
B43: Kendaraan Golongan II | C43: =C19/12500 -> 0 | D43: =D19/12500 -> 0 | E43: =E19/12500 -> 0 | F43: =F19/12500 -> 0 | G43: =G19/12500 -> 0 | H43: =H19/12500 -> 0 | I43: =I19/12500 -> 0 | J43: =J19/12500 -> 0 | ... AD43: =AD19/12500 -> 0 | AE43: =SUM(C43:AD43) -> 0
B44: Kendaraan Golongan III | C44: =C20/6000 -> 0 | D44: =D20/6000 -> 0 | E44: =E20/6000 -> 0 | F44: =F20/6000 -> 0 | G44: =G20/6000 -> 0 | H44: =H20/6000 -> 0 | I44: =I20/6000 -> 0 | J44: =J20/6000 -> 0 | ... AD44: =AD20/6000 -> 0 | AE44: =SUM(C44:AD44) -> 0
...

Sheet mARET 26
A1: DATA RINCIAN PENDAPATAN E-TICKETING NEW GATE BULAN MARET 2026
A3: NO | B3: JENIS PENDAPATAN | C3: TANGGAL | AH3: JUMLAH | AM3: PENDAPATAN
C4: 1 | D4: 2 | E4: 3 | F4: 4 | G4: 5 | H4: 6 | I4: 7 | J4: 8 | K4: 9 | L4: 10 | M4: 11 | N4: 12 | O4: 13 | P4: 14 | Q4: 15 | R4: 16 | S4: 17 | T4: 18 | U4: 19 | V4: 20 | W4: 21 | X4: 22 | Y4: 23 | Z4: 24 | AA4: 25 | AB4: 26 | AC4: 27 | AD4: 28 | AE4: 29 | AF4: 30 | AG4: 31 | AM4: TAMAN MARGASATWA RAGUNAN 2018 :
A5: 1 | B5: Dewasa | C5: 4360000 | E5: 488000 | F5: 828000 | G5: 324000 | H5: 240000 | I5: 2492000 | J5: 1780000 | L5: 796000 | M5: 992000 | N5: 944000 | O5: 836000 | P5: 3128000 | Q5: 3780000 | S5: 2292000 | T5: 3296000 | U5: 7552000 | V5: 6112000 | X5: 65300000 | Y5: 56216000 | Z5: 48240000 | AA5: 38252000 | AB5: 26124000 | AC5: 19300000 | AD5: 35668000 | AE5: 40856000 | AG5: 10976000 | AH5: =SUM(C5:AG5) -> 381172000 | AI5: =AH5/4000 -> 95293 | AJ5: 177844000 | AK5: =AH5+AJ5 -> 559016000 | AM5: Dewasa | AN5: =AH5 -> 381172000
A6: 2 | B6: Anak | C6: 774000 | E6: 39000 | F6: 111000 | G6: 27000 | H6: 15000 | I6: 384000 | J6: 321000 | L6: 81000 | M6: 120000 | N6: 99000 | O6: 96000 | P6: =1104000+537000 -> 1641000 | Q6: 690000 | S6: 552000 | T6: 777000 | U6: 1728000 | V6: 1368000 | X6: 17430000 | Y6: 16911000 | Z6: 15021000 | AA6: 11619000 | AB6: 8235000 | AC6: 6114000 | AD6: 10782000 | AE6: 11331000 | AG6: 2568000 | AH6: =SUM(C6:AG6) -> 108834000 | AI6: =AH6/3000 -> 36278 | AJ6: 38136000 | AK6: =AH6+AJ6 -> 146970000 | AM6: Anak | AN6: =AH6 -> 108834000
A7: 3 | B7: Rombongan Dewasa | AH7: =SUM(C7:AG7) -> 0 | AI7: =AH7/3000 -> 0 | AK7: =AH7+AJ7 -> 0 | AM7: Rombongan Dewasa | AN7: =AH7 -> 0
A8: 4 | B8: Rombongan Anak | AH8: =SUM(C8:AG8) -> 0 | AI8: =AH8/2250 -> 0 | AK8: =AH8+AJ8 -> 0 | AM8: Rombongan Anak | AN8: =AH8 -> 0
A9: 5 | B9: Taman Satwa Anak | C9: 47500 | E9: 7500 | H9: 5000 | I9: 22500 | J9: 25000 | L9: 2500 | M9: 5000 | N9: 10000 | O9: 2500 | P9: 50000 | Q9: 42500 | T9: 70000 | U9: 70000 | V9: 30000 | X9: 1777500 | Y9: 1617500 | Z9: 1387500 | AA9: 625000 | AB9: 465000 | AC9: 375000 | AD9: 867500 | AE9: 1075000 | AG9: 75000 | AH9: =SUM(C9:AG9) -> 8655000 | AI9: =AH9/2500 -> 3462 | AJ9: 21555000 | AK9: =AH9+AJ9 -> 30210000
A10: 6 | B10: PPS Hari Selasa-Jum'at Dewasa | E10: 12000 | F10: 42000 | G10: 18000 | H10: 12000 | L10: 42000 | M10: 36000 | N10: 84000 | O10: 54000 | S10: 138000 | AA10: 9210000 | AB10: 6972000 | AC10: 4242000 | AG10: 390000 | AH10: =SUM(C10:AG10) -> 21252000 | AI10: =AH10/6000 -> 3542 | AJ10: 19644000 | AK10: =AH10+AJ10 -> 40896000 | AM10: Sepeda | AN10: =AH10 -> 21252000
A11: 7 | B11: PPS Hari Selasa-Jum'at Anak | E11: 18000 | F11: 30000 | H11: 12000 | L11: 24000 | N11: 60000 | O11: 24000 | S11: 54000 | AA11: 6972000 | AB11: 5298000 | AC11: 3210000 | AG11: 168000 | AH11: =SUM(C11:AG11) -> 15870000 | AI11: =AH11/6000 -> 2645 | AJ11: 5784000 | AK11: =AH11+AJ11 -> 21654000 | AM11: Kuda Tunggang | AN11: =AH11 -> 15870000
A12: 8 | B12: Romb PPS Hari Selasa-Jum'at Dewasa | AH12: =SUM(C12:AG12) -> 0 | AI12: =AH12/4500 -> 0 | AK12: =AH12+AJ12 -> 0 | AM12: Unta Tunggang | AN12: =AH12 -> 0
A13: 9 | B13: Romb PPS Hari Selasa-Jum'at Anak | AH13: =SUM(C13:AG13) -> 0 | AI13: =AH13/4500 -> 0 | AK13: =AH13+AJ13 -> 0 | AM13: Gajah Tunggang | AN13: =AH13 -> 0
A14: 10 | B14: PPS Hari Sabtu-Minggu/Libur Nasional Dewasa | C14: 210000 | I14: 150000 | J14: 60000 | P14: 202500 | Q14: 232500 | T14: 352500 | U14: 510000 | V14: 307500 | X14: 24862500 | Y14: 20827500 | Z14: 16342500 | AA14: 127500 | AD14: 12382500 | AE14: 14017500 | AH14: =SUM(C14:AG14) -> 90585000 | AI14: =AH14/7500 -> 12078 | AJ14: 73042500 | AK14: =AH14+AJ14 -> 163627500 | AM14: Taman Satwa Anak / Pentas | AN14: =AH14 -> 90585000
A15: 11 | B15: PPS Hari Sabtu-Minggu/Libur Nasional Anak | C15: 225000 | I15: 37500 | J15: 7500 | P15: 210000 | Q15: 82500 | T15: 202500 | U15: 427500 | V15: 187500 | X15: 18675000 | Y15: 16432500 | Z15: 12577500 | AA15: 82500 | AD15: 8760000 | AE15: 9592500 | AH15: =SUM(C15:AG15) -> 67500000 | AI15: =AH15/7500 -> 9000 | AJ15: 20887500 | AK15: =AH15+AJ15 -> 88387500 | AM15: PPS Hari Selasa-Jum'at Dewasa | AN15: =AH15 -> 67500000
A16: 12 | B16: Romb PPS Hari Sabtu-Minggu/Libur Nasional Dewasa | AH16: =SUM(C16:AG16) -> 0 | AI16: =AH16/5625 -> 0 | AK16: =AH16+AJ16 -> 0 | AM16: PPS Hari Selasa-Jum'at Anak | AN16: =AH16 -> 0
A17: 13 | B17: Romb PPS Hari Sabtu-Minggu/Libur Nasional Anak | AH17: =SUM(C17:AG17) -> 0 | AI17: =AH17/5625 -> 0 | AK17: =AH17+AJ17 -> 0 | AM17: Romb PPS Hari Selasa-Jum'at Dewasa | AN17: =AH17 -> 0
A18: 14 | B18: Kendaraan Golongan I | AH18: =SUM(C18:AG18) -> 0 | AI18: =AH18/15000 -> 0 | AJ18: 1065000 | AK18: =AH18+AJ18 -> 1065000 | AM18: Romb PPS Hari Selasa-Jum'at Anak | AN18: =AH18 -> 0
A19: 15 | B19: Kendaraan Golongan II | AH19: =SUM(C19:AG19) -> 0 | AI19: =AH19/12500 -> 0 | AJ19: 725000 | AK19: =AH19+AJ19 -> 725000 | AM19: PPS Hari Sabtu-Minggu/Libur Nasional Dewasa | AN19: =AH19 -> 0
A20: 16 | B20: Kendaraan Golongan III | AH20: =SUM(C20:AG20) -> 0 | AI20: =AH20/6000 -> 0 | AJ20: 16956000 | AK20: =AH20+AJ20 -> 16956000 | AM20: PPS Hari Sabtu-Minggu/Libur Nasional Anak | AN20: =AH20 -> 0
A21: 17 | B21: Sepeda Motor | AH21: =SUM(C21:AG21) -> 0 | AI21: =AH21/3000 -> 0 | AJ21: 13752000 | AK21: =AH21+AJ21 -> 13752000 | AM21: Romb PPS Hari Sabtu-Minggu/Libur Nasional Dewasa | AN21: =AH21 -> 0
A22: 18 | B22: Sepeda | AH22: =SUM(C22:AG22) -> 0 | AI22: =AH22/1000 -> 0 | AJ22: 343000 | AK22: =AH22+AJ22 -> 343000 | AM22: Romb PPS Hari Sabtu-Minggu/Libur Nasional Anak | AN22: =AH22 -> 0
B23: Jumlah | C23: =SUM(C5:C22) -> 5616500 | D23: =SUM(D5:D22) -> 0 | E23: =SUM(E5:E22) -> 564500 | F23: =SUM(F5:F22) -> 1011000 | G23: =SUM(G5:G22) -> 369000 | H23: =SUM(H5:H22) -> 284000 | I23: =SUM(I5:I22) -> 3086000 | J23: =SUM(J5:J22) -> 2193500 | ... AH23: =SUM(AH5:AH22) -> 693868000 | AJ23: =SUM(AJ5:AJ22) -> 389734000 | AM23: Jumlah | AN23: =AH23 -> 693868000
B27: PENGUNJUNG | AM27: ASURANSI LEMBAR
B28: T A N G G A L | C28: 1 | D28: 2 | E28: 3 | F28: 4 | G28: 5 | H28: 6 | I28: 7 | J28: 8 | K28: 9 | L28: 10 | M28: 11 | N28: 12 | O28: 13 | P28: 14 | Q28: 15 | R28: 16 | S28: 17 | T28: 18 | U28: 19 | V28: 20 | W28: 21 | X28: 22 | Y28: 23 | Z28: 24 | AA28: 25 | AB28: 26 | AC28: 27 | AD28: 28 | AE28: 29 | AF28: 30 | AG28: 31 | AH28: jumlah | AM28: T A N G G A L
B29: Dewasa | C29: =C5/4000 -> 1090 | D29: =D5/4000 -> 0 | E29: =E5/4000 -> 122 | F29: =F5/4000 -> 207 | G29: =G5/4000 -> 81 | H29: =H5/4000 -> 60 | I29: =I5/4000 -> 623 | J29: =J5/4000 -> 445 | ... AG29: =AG5/4000 -> 2744 | AH29: =SUM(C29:AG29) -> 95293 | AM29: Dewasa | AN29: =AH29 -> 95293
B30: Anak | C30: =C6/3000 -> 258 | D30: =D6/3000 -> 0 | E30: =E6/3000 -> 13 | F30: =F6/3000 -> 37 | G30: =G6/3000 -> 9 | H30: =H6/3000 -> 5 | I30: =I6/3000 -> 128 | J30: =J6/3000 -> 107 | ... AG30: =AG6/3000 -> 856 | AH30: =SUM(C30:AG30) -> 36278 | AM30: Anak | AN30: =AH30 -> 36278
B31: Rombongan Dewasa | C31: =C7/3000 -> 0 | D31: =D7/3000 -> 0 | E31: =E7/3000 -> 0 | F31: =F7/3000 -> 0 | G31: =G7/3000 -> 0 | H31: =H7/3000 -> 0 | I31: =I7/3000 -> 0 | J31: =J7/3000 -> 0 | ... AG31: =AG7/3000 -> 0 | AH31: =SUM(C31:AG31) -> 0 | AM31: Rombongan Dewasa | AN31: =AH31 -> 0
B32: Rombongan Anak | C32: =C8/2250 -> 0 | D32: =D8/2250 -> 0 | E32: =E8/2250 -> 0 | F32: =F8/2250 -> 0 | G32: =G8/2250 -> 0 | H32: =H8/2250 -> 0 | I32: =I8/2250 -> 0 | J32: =J8/2250 -> 0 | ... AG32: =AG8/2250 -> 0 | AH32: =SUM(C32:AG32) -> 0 | AM32: Rombongan Anak | AN32: =AH32 -> 0
B33: Taman Satwa Anak | C33: =C9/2500 -> 19 | D33: =D9/2500 -> 0 | E33: =E9/2500 -> 3 | F33: =F9/2500 -> 0 | G33: =G9/2500 -> 0 | H33: =H9/2500 -> 2 | I33: =I9/2500 -> 9 | J33: =J9/2500 -> 10 | ... AG33: =AG9/2500 -> 30 | AH33: =SUM(C33:AG33) -> 3462
B34: PPS Hari Selasa-Jum'at Dewasa | C34: =C10/6000 -> 0 | D34: =D10/6000 -> 0 | E34: =E10/6000 -> 2 | F34: =F10/6000 -> 7 | G34: =G10/6000 -> 3 | H34: =H10/6000 -> 2 | I34: =I10/6000 -> 0 | J34: =J10/6000 -> 0 | ... AG34: =AG10/6000 -> 65 | AH34: =SUM(C34:AG34) -> 3542 | AM34: Sepeda | AN34: =AH34 -> 3542
B35: PPS Hari Selasa-Jum'at Anak | C35: =C11/6000 -> 0 | D35: =D11/6000 -> 0 | E35: =E11/6000 -> 3 | F35: =F11/6000 -> 5 | G35: =G11/6000 -> 0 | H35: =H11/6000 -> 2 | I35: =I11/6000 -> 0 | J35: =J11/6000 -> 0 | ... AG35: =AG11/6000 -> 28 | AH35: =SUM(C35:AG35) -> 2645 | AM35: JUMLAH Rp | AN35: =AH35 -> 2645
B36: Romb PPS Hari Selasa-Jum'at Dewasa | C36: =C12/4500 -> 0 | D36: =D12/4500 -> 0 | E36: =E12/4500 -> 0 | F36: =F12/4500 -> 0 | G36: =G12/4500 -> 0 | H36: =H12/4500 -> 0 | I36: =I12/4500 -> 0 | J36: =J12/4500 -> 0 | ... AG36: =AG12/4500 -> 0 | AH36: =SUM(C36:AG36) -> 0 | AM36: PPS Dewasa | AN36: =AH36 -> 0
B37: Romb PPS Hari Selasa-Jum'at Anak | C37: =C13/4500 -> 0 | D37: =D13/4500 -> 0 | E37: =E13/4500 -> 0 | F37: =F13/4500 -> 0 | G37: =G13/4500 -> 0 | H37: =H13/4500 -> 0 | I37: =I13/4500 -> 0 | J37: =J13/4500 -> 0 | ... AG37: =AG13/4500 -> 0 | AH37: =SUM(C37:AG37) -> 0 | AM37: PPS Anak | AN37: =AH37 -> 0
B38: PPS Hari Sabtu-Minggu/Libur Nasional Dewasa | C38: =C14/7500 -> 28 | D38: =D14/7500 -> 0 | E38: =E14/7500 -> 0 | F38: =F14/7500 -> 0 | G38: =G14/7500 -> 0 | H38: =H14/7500 -> 0 | I38: =I14/7500 -> 20 | J38: =J14/7500 -> 8 | ... AG38: =AG14/7500 -> 0 | AH38: =SUM(C38:AG38) -> 12078 | AM38: PPS Romb.Dewasa | AN38: =AH38 -> 12078
B39: PPS Hari Sabtu-Minggu/Libur Nasional Anak | C39: =C15/7500 -> 30 | D39: =D15/7500 -> 0 | E39: =E15/7500 -> 0 | F39: =F15/7500 -> 0 | G39: =G15/7500 -> 0 | H39: =H15/7500 -> 0 | I39: =I15/7500 -> 5 | J39: =J15/7500 -> 1 | ... AG39: =AG15/7500 -> 0 | AH39: =SUM(C39:AG39) -> 9000 | AM39: PPS Romb. Anak | AN39: =AH39 -> 9000
B40: Romb PPS Hari Sabtu-Minggu/Libur Nasional Dewasa | C40: =C16/5625 -> 0 | D40: =D16/5625 -> 0 | E40: =E16/5625 -> 0 | F40: =F16/5625 -> 0 | G40: =G16/5625 -> 0 | H40: =H16/5625 -> 0 | I40: =I16/5625 -> 0 | J40: =J16/5625 -> 0 | ... AG40: =AG16/5625 -> 0 | AH40: =SUM(C40:AG40) -> #VALUE! | AM40: JUMLAH Rp | AN40: =AH40 -> #VALUE!
B41: Romb PPS Hari Sabtu-Minggu/Libur Nasional Anak | C41: =C17/5625 -> 0 | D41: =D17/5625 -> 0 | E41: =E17/5625 -> 0 | F41: =F17/5625 -> 0 | G41: =G17/5625 -> 0 | H41: =H17/5625 -> 0 | I41: =I17/5625 -> 0 | J41: =J17/5625 -> 0 | ... AG41: =AG17/5625 -> 0 | AH41: =SUM(C41:AG41) -> 0
B42: Kendaraan Golongan I | C42: =C18/15000 -> 0 | D42: =D18/15000 -> 0 | E42: =E18/15000 -> 0 | F42: =F18/15000 -> 0 | G42: =G18/15000 -> 0 | H42: =H18/15000 -> 0 | I42: =I18/15000 -> 0 | J42: =J18/15000 -> 0 | ... AG42: =AG18/15000 -> 0 | AH42: =SUM(C42:AG42) -> 0
B43: Kendaraan Golongan II | C43: =C19/12500 -> 0 | D43: =D19/12500 -> 0 | E43: =E19/12500 -> 0 | F43: =F19/12500 -> 0 | G43: =G19/12500 -> 0 | H43: =H19/12500 -> 0 | I43: =I19/12500 -> 0 | J43: =J19/12500 -> 0 | ... AG43: =AG19/12500 -> 0 | AH43: =SUM(C43:AG43) -> 0
B44: Kendaraan Golongan III | C44: =C20/6000 -> 0 | D44: =D20/6000 -> 0 | E44: =E20/6000 -> 0 | F44: =F20/6000 -> 0 | G44: =G20/6000 -> 0 | H44: =H20/6000 -> 0 | I44: =I20/6000 -> 0 | J44: =J20/6000 -> 0 | ... AG44: =AG20/6000 -> 0 | AH44: =SUM(C44:AG44) -> 0
...

Sheet APRIL 26
A1: DATA RINCIAN PENDAPATAN E-TICKETING NEW GATE BULAN APRIL 2026
A3: NO | B3: JENIS PENDAPATAN | C3: TANGGAL | AG3: JUMLAH | AL3: PENDAPATAN
C4: 1 | D4: 2 | E4: 3 | F4: 4 | G4: 5 | H4: 6 | I4: 7 | J4: 8 | K4: 9 | L4: 10 | M4: 11 | N4: 12 | O4: 13 | P4: 14 | Q4: 15 | R4: 16 | S4: 17 | T4: 18 | U4: 19 | V4: 20 | W4: 21 | X4: 22 | Y4: 23 | Z4: 24 | AA4: 25 | AB4: 26 | AC4: 27 | AD4: 28 | AE4: 29 | AF4: 30 | AL4: TAMAN MARGASATWA RAGUNAN 2018 :
A5: 1 | B5: Dewasa | C5: 8720000 | D5: 9708000 | E5: 28644000 | F5: 27616000 | G5: 49512000 | I5: 7476000 | J5: 5896000 | K5: 6340000 | L5: 5740000 | M5: 21268000 | N5: 36020000 | P5: 6652000 | Q5: 6828000 | R5: 6100000 | S5: 5020000 | T5: 27860000 | U5: 32284000 | W5: 6468000 | X5: 5456000 | Y5: 4700000 | Z5: 5408000 | AA5: 19944000 | AB5: 30880000 | AD5: 4648000 | AE5: 6348000 | AF5: 6440000 | AG5: =SUM(C5:AF5) -> 381976000 | AH5: =AG5/4000 -> 95494 | AI5: 198824000 | AJ5: =AG5+AI5 -> 580800000 | AL5: Dewasa | AM5: =AG5 -> 381976000
A6: 2 | B6: Anak | C6: 2115000 | D6: 2034000 | E6: 7923000 | F6: 7422000 | G6: 13146000 | I6: 1149000 | J6: 873000 | K6: 1056000 | L6: 870000 | M6: 4575000 | N6: 8622000 | P6: 987000 | Q6: 1029000 | R6: 993000 | S6: 714000 | T6: 5961000 | U6: 7095000 | W6: 867000 | X6: 918000 | Y6: 699000 | Z6: 690000 | AA6: 3987000 | AB6: 6609000 | AD6: 780000 | AE6: 945000 | AF6: 966000 | AG6: =SUM(C6:AF6) -> 83025000 | AH6: =AG6/3000 -> 27675 | AI6: 33195000 | AJ6: =AG6+AI6 -> 116220000 | AL6: Anak | AM6: =AG6 -> 83025000
A7: 3 | B7: Rombongan Dewasa | AG7: =SUM(C7:AF7) -> 0 | AH7: =AG7/3000 -> 0 | AJ7: =AG7+AI7 -> 0 | AL7: Rombongan Dewasa | AM7: =AG7 -> 0
A8: 4 | B8: Rombongan Anak | AG8: =SUM(C8:AF8) -> 0 | AH8: =AG8/2250 -> 0 | AJ8: =AG8+AI8 -> 0 | AL8: Rombongan Anak | AM8: =AG8 -> 0
A9: 5 | B9: Taman Satwa Anak | C9: 62500 | D9: 162500 | E9: 565000 | F9: 690000 | G9: 1467500 | I9: 62500 | J9: 27500 | K9: 65000 | L9: 77500 | M9: 687500 | N9: 1242500 | P9: 17500 | Q9: 90000 | R9: 127500 | S9: 107500 | T9: 735000 | U9: 1170000 | W9: 20000 | X9: 162500 | Y9: 35000 | Z9: 40000 | AA9: 617500 | AB9: 930000 | AD9: 82500 | AE9: 95000 | AF9: 42500 | AG9: =SUM(C9:AF9) -> 9382500 | AH9: =AG9/2500 -> 3753 | AI9: 21035000 | AJ9: =AG9+AI9 -> 30417500
A10: 6 | B10: PPS Hari Selasa-Jum'at Dewasa | C10: 498000 | D10: 432000 | I10: 252000 | J10: 258000 | K10: 354000 | L10: 192000 | P10: 246000 | Q10: 186000 | R10: 348000 | S10: 288000 | W10: 282000 | X10: 186000 | Y10: 186000 | Z10: 174000 | AD10: 360000 | AE10: 198000 | AF10: 366000 | AG10: =SUM(C10:AF10) -> 4806000 | AH10: =AG10/6000 -> 801 | AI10: 20982000 | AJ10: =AG10+AI10 -> 25788000 | AL10: Sepeda | AM10: =AG10 -> 4806000
A11: 7 | B11: PPS Hari Selasa-Jum'at Anak | C11: 180000 | D11: 168000 | I11: 150000 | J11: 126000 | K11: 168000 | L11: 138000 | P11: 168000 | Q11: 108000 | R11: 120000 | S11: 216000 | W11: 138000 | X11: 132000 | Y11: 36000 | Z11: 120000 | AD11: 114000 | AE11: 90000 | AF11: 90000 | AG11: =SUM(C11:AF11) -> 2262000 | AH11: =AG11/6000 -> 377 | AI11: 4392000 | AJ11: =AG11+AI11 -> 6654000 | AL11: Kuda Tunggang | AM11: =AG11 -> 2262000
A12: 8 | B12: Romb PPS Hari Selasa-Jum'at Dewasa | AG12: =SUM(C12:AF12) -> 0 | AH12: =AG12/4500 -> 0 | AJ12: =AG12+AI12 -> 0 | AL12: Unta Tunggang | AM12: =AG12 -> 0
A13: 9 | B13: Romb PPS Hari Selasa-Jum'at Anak | AG13: =SUM(C13:AF13) -> 0 | AH13: =AG13/4500 -> 0 | AJ13: =AG13+AI13 -> 0 | AL13: Gajah Tunggang | AM13: =AG13 -> 0
A14: 10 | B14: PPS Hari Sabtu-Minggu/Libur Nasional Dewasa | E14: 7462500 | F14: 4282500 | G14: 5647500 | M14: 3622500 | N14: 7882500 | T14: 4215000 | U14: 6645000 | AA14: 4102500 | AB14: 5265000 | AG14: =SUM(C14:AF14) -> 49125000 | AH14: =AG14/7500 -> 6550 | AI14: 82710000 | AJ14: =AG14+AI14 -> 131835000 | AL14: Taman Satwa Anak / Pentas | AM14: =AG14 -> 49125000
A15: 11 | B15: PPS Hari Sabtu-Minggu/Libur Nasional Anak | E15: 5790000 | F15: 3097500 | G15: 4942500 | M15: 2655000 | N15: 5347500 | T15: 2805000 | U15: 4740000 | AA15: 2760000 | AB15: 4072500 | AG15: =SUM(C15:AF15) -> 36210000 | AH15: =AG15/7500 -> 4828 | AI15: 19380000 | AJ15: =AG15+AI15 -> 55590000 | AL15: PPS Hari Selasa-Jum'at Dewasa | AM15: =AG15 -> 36210000
A16: 12 | B16: Romb PPS Hari Sabtu-Minggu/Libur Nasional Dewasa | AG16: =SUM(C16:AF16) -> 0 | AH16: =AG16/5625 -> 0 | AJ16: =AG16+AI16 -> 0 | AL16: PPS Hari Selasa-Jum'at Anak | AM16: =AG16 -> 0
A17: 13 | B17: Romb PPS Hari Sabtu-Minggu/Libur Nasional Anak | AG17: =SUM(C17:AF17) -> 0 | AH17: =AG17/5625 -> 0 | AJ17: =AG17+AI17 -> 0 | AL17: Romb PPS Hari Selasa-Jum'at Dewasa | AM17: =AG17 -> 0
A18: 14 | B18: Kendaraan Golongan I | AG18: =SUM(C18:AF18) -> 0 | AH18: =AG18/15000 -> 0 | AI18: 960000 | AJ18: =AG18+AI18 -> 960000 | AL18: Romb PPS Hari Selasa-Jum'at Anak | AM18: =AG18 -> 0
A19: 15 | B19: Kendaraan Golongan II | AG19: =SUM(C19:AF19) -> 0 | AH19: =AG19/12500 -> 0 | AI19: 512500 | AJ19: =AG19+AI19 -> 512500 | AL19: PPS Hari Sabtu-Minggu/Libur Nasional Dewasa | AM19: =AG19 -> 0
A20: 16 | B20: Kendaraan Golongan III | AG20: =SUM(C20:AF20) -> 0 | AH20: =AG20/6000 -> 0 | AI20: 18366000 | AJ20: =AG20+AI20 -> 18366000 | AL20: PPS Hari Sabtu-Minggu/Libur Nasional Anak | AM20: =AG20 -> 0
A21: 17 | B21: Sepeda Motor | AG21: =SUM(C21:AF21) -> 0 | AH21: =AG21/3000 -> 0 | AI21: 19251000 | AJ21: =AG21+AI21 -> 19251000 | AL21: Romb PPS Hari Sabtu-Minggu/Libur Nasional Dewasa | AM21: =AG21 -> 0
A22: 18 | B22: Sepeda | AG22: =SUM(C22:AF22) -> 0 | AH22: =AG22/1000 -> 0 | AI22: 910000 | AJ22: =AG22+AI22 -> 910000 | AL22: Romb PPS Hari Sabtu-Minggu/Libur Nasional Anak | AM22: =AG22 -> 0
B23: Jumlah | C23: =SUM(C5:C22) -> 11575500 | D23: =SUM(D5:D22) -> 12504500 | E23: =SUM(E5:E22) -> 50384500 | F23: =SUM(F5:F22) -> 43108000 | G23: =SUM(G5:G22) -> 74715500 | H23: =SUM(H5:H22) -> 0 | I23: =SUM(I5:I22) -> 9089500 | J23: =SUM(J5:J22) -> 7180500 | ... AG23: =SUM(AG5:AG22) -> 566786500 | AI23: =SUM(AI5:AI22) -> 420517500 | AL23: Jumlah | AM23: =AG23 -> 566786500
B27: PENGUNJUNG | AL27: ASURANSI LEMBAR
B28: T A N G G A L | C28: 1 | D28: 2 | E28: 3 | F28: 4 | G28: 5 | H28: 6 | I28: 7 | J28: 8 | K28: 9 | L28: 10 | M28: 11 | N28: 12 | O28: 13 | P28: 14 | Q28: 15 | R28: 16 | S28: 17 | T28: 18 | U28: 19 | V28: 20 | W28: 21 | X28: 22 | Y28: 23 | Z28: 24 | AA28: 25 | AB28: 26 | AC28: 27 | AD28: 28 | AE28: 29 | AF28: 30 | AG28: jumlah | AL28: T A N G G A L
B29: Dewasa | C29: =C5/4000 -> 2180 | D29: =D5/4000 -> 2427 | E29: =E5/4000 -> 7161 | F29: =F5/4000 -> 6904 | G29: =G5/4000 -> 12378 | H29: =H5/4000 -> 0 | I29: =I5/4000 -> 1869 | J29: =J5/4000 -> 1474 | ... AF29: =AF5/4000 -> 1610 | AG29: =SUM(C29:AF29) -> 95494 | AL29: Dewasa | AM29: =AG29 -> 95494
B30: Anak | C30: =C6/3000 -> 705 | D30: =D6/3000 -> 678 | E30: =E6/3000 -> 2641 | F30: =F6/3000 -> 2474 | G30: =G6/3000 -> 4382 | H30: =H6/3000 -> 0 | I30: =I6/3000 -> 383 | J30: =J6/3000 -> 291 | ... AF30: =AF6/3000 -> 322 | AG30: =SUM(C30:AF30) -> 27675 | AL30: Anak | AM30: =AG30 -> 27675
B31: Rombongan Dewasa | C31: =C7/3000 -> 0 | D31: =D7/3000 -> 0 | E31: =E7/3000 -> 0 | F31: =F7/3000 -> 0 | G31: =G7/3000 -> 0 | H31: =H7/3000 -> 0 | I31: =I7/3000 -> 0 | J31: =J7/3000 -> 0 | ... AF31: =AF7/3000 -> 0 | AG31: =SUM(C31:AF31) -> 0 | AL31: Rombongan Dewasa | AM31: =AG31 -> 0
B32: Rombongan Anak | C32: =C8/2250 -> 0 | D32: =D8/2250 -> 0 | E32: =E8/2250 -> 0 | F32: =F8/2250 -> 0 | G32: =G8/2250 -> 0 | H32: =H8/2250 -> 0 | I32: =I8/2250 -> 0 | J32: =J8/2250 -> 0 | ... AF32: =AF8/2250 -> 0 | AG32: =SUM(C32:AF32) -> 0 | AL32: Rombongan Anak | AM32: =AG32 -> 0
B33: Taman Satwa Anak | C33: =C9/2500 -> 25 | D33: =D9/2500 -> 65 | E33: =E9/2500 -> 226 | F33: =F9/2500 -> 276 | G33: =G9/2500 -> 587 | H33: =H9/2500 -> 0 | I33: =I9/2500 -> 25 | J33: =J9/2500 -> 11 | ... AF33: =AF9/2500 -> 17 | AG33: =SUM(C33:AF33) -> 3753
B34: PPS Hari Selasa-Jum'at Dewasa | C34: =C10/6000 -> 83 | D34: =D10/6000 -> 72 | E34: =E10/6000 -> 0 | F34: =F10/6000 -> 0 | G34: =G10/6000 -> 0 | H34: =H10/6000 -> 0 | I34: =I10/6000 -> 42 | J34: =J10/6000 -> 43 | ... AF34: =AF10/6000 -> 61 | AG34: =SUM(C34:AF34) -> 801 | AL34: Sepeda | AM34: =AG34 -> 801
B35: PPS Hari Selasa-Jum'at Anak | C35: =C11/6000 -> 30 | D35: =D11/6000 -> 28 | E35: =E11/6000 -> 0 | F35: =F11/6000 -> 0 | G35: =G11/6000 -> 0 | H35: =H11/6000 -> 0 | I35: =I11/6000 -> 25 | J35: =J11/6000 -> 21 | ... AF35: =AF11/6000 -> 15 | AG35: =SUM(C35:AF35) -> 377 | AL35: JUMLAH Rp | AM35: =AG35 -> 377
B36: Romb PPS Hari Selasa-Jum'at Dewasa | C36: =C12/4500 -> 0 | D36: =D12/4500 -> 0 | E36: =E12/4500 -> 0 | F36: =F12/4500 -> 0 | G36: =G12/4500 -> 0 | H36: =H12/4500 -> 0 | I36: =I12/4500 -> 0 | J36: =J12/4500 -> 0 | ... AF36: =AF12/4500 -> 0 | AG36: =SUM(C36:AF36) -> 0 | AL36: PPS Dewasa | AM36: =AG36 -> 0
B37: Romb PPS Hari Selasa-Jum'at Anak | C37: =C13/4500 -> 0 | D37: =D13/4500 -> 0 | E37: =E13/4500 -> 0 | F37: =F13/4500 -> 0 | G37: =G13/4500 -> 0 | H37: =H13/4500 -> 0 | I37: =I13/4500 -> 0 | J37: =J13/4500 -> 0 | ... AF37: =AF13/4500 -> 0 | AG37: =SUM(C37:AF37) -> 0 | AL37: PPS Anak | AM37: =AG37 -> 0
B38: PPS Hari Sabtu-Minggu/Libur Nasional Dewasa | C38: =C14/7500 -> 0 | D38: =D14/7500 -> 0 | E38: =E14/7500 -> 995 | F38: =F14/7500 -> 571 | G38: =G14/7500 -> 753 | H38: =H14/7500 -> 0 | I38: =I14/7500 -> 0 | J38: =J14/7500 -> 0 | ... AF38: =AF14/7500 -> 0 | AG38: =SUM(C38:AF38) -> 6550 | AL38: PPS Romb.Dewasa | AM38: =AG38 -> 6550
B39: PPS Hari Sabtu-Minggu/Libur Nasional Anak | C39: =C15/7500 -> 0 | D39: =D15/7500 -> 0 | E39: =E15/7500 -> 772 | F39: =F15/7500 -> 413 | G39: =G15/7500 -> 659 | H39: =H15/7500 -> 0 | I39: =I15/7500 -> 0 | J39: =J15/7500 -> 0 | ... AF39: =AF15/7500 -> 0 | AG39: =SUM(C39:AF39) -> 4828 | AL39: PPS Romb. Anak | AM39: =AG39 -> 4828
B40: Romb PPS Hari Sabtu-Minggu/Libur Nasional Dewasa | C40: =C16/5625 -> 0 | D40: =D16/5625 -> 0 | E40: =E16/5625 -> 0 | F40: =F16/5625 -> 0 | G40: =G16/5625 -> 0 | H40: =H16/5625 -> 0 | I40: =I16/5625 -> 0 | J40: =J16/5625 -> 0 | ... AF40: =AF16/5625 -> 0 | AG40: =SUM(C40:AF40) -> 0 | AL40: JUMLAH Rp | AM40: =AG40 -> 0
B41: Romb PPS Hari Sabtu-Minggu/Libur Nasional Anak | C41: =C17/5625 -> 0 | D41: =D17/5625 -> 0 | E41: =E17/5625 -> 0 | F41: =F17/5625 -> 0 | G41: =G17/5625 -> 0 | H41: =H17/5625 -> 0 | I41: =I17/5625 -> 0 | J41: =J17/5625 -> 0 | ... AF41: =AF17/5625 -> 0 | AG41: =SUM(C41:AF41) -> 0
B42: Kendaraan Golongan I | C42: =C18/15000 -> 0 | D42: =D18/15000 -> 0 | E42: =E18/15000 -> 0 | F42: =F18/15000 -> 0 | G42: =G18/15000 -> 0 | H42: =H18/15000 -> 0 | I42: =I18/15000 -> 0 | J42: =J18/15000 -> 0 | ... AF42: =AF18/15000 -> 0 | AG42: =SUM(C42:AF42) -> 0
B43: Kendaraan Golongan II | C43: =C19/12500 -> 0 | D43: =D19/12500 -> 0 | E43: =E19/12500 -> 0 | F43: =F19/12500 -> 0 | G43: =G19/12500 -> 0 | H43: =H19/12500 -> 0 | I43: =I19/12500 -> 0 | J43: =J19/12500 -> 0 | ... AF43: =AF19/12500 -> 0 | AG43: =SUM(C43:AF43) -> 0
B44: Kendaraan Golongan III | C44: =C20/6000 -> 0 | D44: =D20/6000 -> 0 | E44: =E20/6000 -> 0 | F44: =F20/6000 -> 0 | G44: =G20/6000 -> 0 | H44: =H20/6000 -> 0 | I44: =I20/6000 -> 0 | J44: =J20/6000 -> 0 | ... AF44: =AF20/6000 -> 0 | AG44: =SUM(C44:AF44) -> 0
...

Sheet mei 26
A1: DATA RINCIAN PENDAPATAN E-TICKETING NEW GATE BULAN MEI 2026
A3: NO | B3: JENIS PENDAPATAN | C3: TANGGAL | AH3: JUMLAH | AM3: PENDAPATAN
C4: 1 | D4: 2 | E4: 3 | F4: 4 | G4: 5 | H4: 6 | I4: 7 | J4: 8 | K4: 9 | L4: 10 | M4: 11 | N4: 12 | O4: 13 | P4: 14 | Q4: 15 | R4: 16 | S4: 17 | T4: 18 | U4: 19 | V4: 20 | W4: 21 | X4: 22 | Y4: 23 | Z4: 24 | AA4: 25 | AB4: 26 | AC4: 27 | AD4: 28 | AE4: 29 | AF4: 30 | AG4: 31 | AM4: TAMAN MARGASATWA RAGUNAN 2018 :
A5: 1 | B5: Dewasa | C5: 25024000 | D5: 30080000 | E5: 35416000 | G5: 6988000 | H5: 6340000 | I5: 6372000 | J5: 6368000 | K5: 23968000 | L5: 31836000 | N5: 7132000 | O5: 6692000 | P5: 31184000 | Q5: 18428000 | R5: 25404000 | S5: 31092000 | U5: 5968000 | V5: 4564000 | W5: 4820000 | X5: 4212000 | Y5: 17236000 | Z5: 20424000 | AB5: 4108000 | AC5: 17612000 | AD5: 21396000 | AE5: 6960000 | AF5: 23232000 | AG5: 34548000 | AH5: =SUM(C5:AG5) -> 457404000 | AI5: =AH5/4000 -> 114351 | AJ5: 301028000 | AK5: =AH5+AJ5 -> 758432000 | AM5: Dewasa | AN5: =AH5 -> 457404000
A6: 2 | B6: Anak | C6: 5646000 | D6: 7203000 | E6: 7905000 | G6: 1026000 | H6: 972000 | I6: 1062000 | J6: 1059000 | K6: 4920000 | L6: 6489000 | N6: 810000 | O6: 870000 | P6: 7275000 | Q6: 4668000 | R6: 6300000 | S6: 7062000 | U6: 813000 | V6: 591000 | W6: 654000 | X6: 537000 | Y6: 3147000 | Z6: 4008000 | AB6: 639000 | AC6: 3783000 | AD6: 5571000 | AE6: 1155000 | AF6: 5388000 | AG6: 7929000 | AH6: =SUM(C6:AG6) -> 97482000 | AI6: =AH6/3000 -> 32494 | AJ6: 49170000 | AK6: =AH6+AJ6 -> 146652000 | AM6: Anak | AN6: =AH6 -> 97482000
A7: 3 | B7: Rombongan Dewasa | AH7: =SUM(C7:AG7) -> 0 | AI7: =AH7/3000 -> 0 | AK7: =AH7+AJ7 -> 0 | AM7: Rombongan Dewasa | AN7: =AH7 -> 0
A8: 4 | B8: Rombongan Anak | AH8: =SUM(C8:AG8) -> 0 | AI8: =AH8/2250 -> 0 | AK8: =AH8+AJ8 -> 0 | AM8: Rombongan Anak | AN8: =AH8 -> 0
A9: 5 | B9: Taman Satwa Anak | C9: 677500 | D9: 830000 | E9: 1325000 | G9: 37500 | H9: 157500 | I9: 87500 | J9: 42500 | K9: 662500 | L9: 1000000 | N9: 102500 | O9: 40000 | P9: 1055000 | Q9: 392500 | R9: 687500 | S9: 1100000 | U9: 5000 | V9: 30000 | W9: 47500 | X9: 15000 | Y9: 472500 | Z9: 625000 | AB9: 117500 | AC9: 412500 | AD9: 520000 | AE9: 42500 | AF9: 540000 | AG9: 1265000 | AH9: =SUM(C9:AG9) -> 12290000 | AI9: =AH9/2500 -> 4916 | AJ9: 30565000 | AK9: =AH9+AJ9 -> 42855000
A10: 6 | B10: PPS Hari Selasa-Jum'at Dewasa | G10: 420000 | H10: 396000 | I10: 498000 | J10: 390000 | N10: 378000 | O10: 456000 | U10: 426000 | V10: 318000 | W10: 396000 | X10: 222000 | AB10: 264000 | AE10: 738000 | AH10: =SUM(C10:AG10) -> 4902000 | AI10: =AH10/6000 -> 817 | AJ10: 13542000 | AK10: =AH10+AJ10 -> 18444000 | AM10: Sepeda | AN10: =AH10 -> 4902000
A11: 7 | B11: PPS Hari Selasa-Jum'at Anak | G11: 276000 | H11: 288000 | I11: 294000 | J11: 210000 | N11: 282000 | O11: 336000 | U11: 354000 | V11: 204000 | W11: 264000 | X11: 120000 | AB11: 198000 | AE11: 426000 | AH11: =SUM(C11:AG11) -> 3252000 | AI11: =AH11/6000 -> 542 | AJ11: 3144000 | AK11: =AH11+AJ11 -> 6396000 | AM11: Kuda Tunggang | AN11: =AH11 -> 3252000
A12: 8 | B12: Romb PPS Hari Selasa-Jum'at Dewasa | AH12: =SUM(C12:AG12) -> 0 | AI12: =AH12/4500 -> 0 | AK12: =AH12+AJ12 -> 0 | AM12: Unta Tunggang | AN12: =AH12 -> 0
A13: 9 | B13: Romb PPS Hari Selasa-Jum'at Anak | AH13: =SUM(C13:AG13) -> 0 | AI13: =AH13/4500 -> 0 | AK13: =AH13+AJ13 -> 0 | AM13: Gajah Tunggang | AN13: =AH13 -> 0
A14: 10 | B14: PPS Hari Sabtu-Minggu/Libur Nasional Dewasa | C14: 5377500 | D14: 8197500 | E14: 9015000 | K14: 5655000 | L14: 9525000 | P14: 8077500 | Q14: 3990000 | R14: 6172500 | S14: 7620000 | Y14: 3337500 | Z14: 4155000 | AC14: 3780000 | AD14: 4500000 | AF14: 5407500 | AG14: 11070000 | AH14: =SUM(C14:AG14) -> 95880000 | AI14: =AH14/7500 -> 12784 | AJ14: 141435000 | AK14: =AH14+AJ14 -> 237315000 | AM14: Taman Satwa Anak / Pentas | AN14: =AH14 -> 95880000
A15: 11 | B15: PPS Hari Sabtu-Minggu/Libur Nasional Anak | C15: 3705000 | D15: 5362500 | E15: 6360000 | K15: 3802500 | L15: 6772500 | P15: 5497500 | Q15: 2700000 | R15: 4372500 | S15: 5392500 | Y15: 2302500 | Z15: 3202500 | AC15: 2437500 | AD15: 3397500 | AF15: 3877500 | AG15: 7312500 | AH15: =SUM(C15:AG15) -> 66495000 | AI15: =AH15/7500 -> 8866 | AJ15: 32760000 | AK15: =AH15+AJ15 -> 99255000 | AM15: PPS Hari Selasa-Jum'at Dewasa | AN15: =AH15 -> 66495000
A16: 12 | B16: Romb PPS Hari Sabtu-Minggu/Libur Nasional Dewasa | AG16: , | AH16: =SUM(C16:AG16) -> 0 | AI16: =AH16/5625 -> 0 | AK16: =AH16+AJ16 -> 0 | AM16: PPS Hari Selasa-Jum'at Anak | AN16: =AH16 -> 0
A17: 13 | B17: Romb PPS Hari Sabtu-Minggu/Libur Nasional Anak | AH17: =SUM(C17:AG17) -> 0 | AI17: =AH17/5625 -> 0 | AK17: =AH17+AJ17 -> 0 | AM17: Romb PPS Hari Selasa-Jum'at Dewasa | AN17: =AH17 -> 0
A18: 14 | B18: Kendaraan Golongan I | AH18: =SUM(C18:AG18) -> 0 | AI18: =AH18/15000 -> 0 | AJ18: 1590000 | AK18: =AH18+AJ18 -> 1590000 | AM18: Romb PPS Hari Selasa-Jum'at Anak | AN18: =AH18 -> 0
A19: 15 | B19: Kendaraan Golongan II | AH19: =SUM(C19:AG19) -> 0 | AI19: =AH19/12500 -> 0 | AJ19: 1200000 | AK19: =AH19+AJ19 -> 1200000 | AM19: PPS Hari Sabtu-Minggu/Libur Nasional Dewasa | AN19: =AH19 -> 0
A20: 16 | B20: Kendaraan Golongan III | AH20: =SUM(C20:AG20) -> 0 | AI20: =AH20/6000 -> 0 | AJ20: 29664000 | AK20: =AH20+AJ20 -> 29664000 | AM20: PPS Hari Sabtu-Minggu/Libur Nasional Anak | AN20: =AH20 -> 0
A21: 17 | B21: Sepeda Motor | AH21: =SUM(C21:AG21) -> 0 | AI21: =AH21/3000 -> 0 | AJ21: 28908000 | AK21: =AH21+AJ21 -> 28908000 | AM21: Romb PPS Hari Sabtu-Minggu/Libur Nasional Dewasa | AN21: =AH21 -> 0
A22: 18 | B22: Sepeda | AH22: =SUM(C22:AG22) -> 0 | AI22: =AH22/1000 -> 0 | AJ22: 1645000 | AK22: =AH22+AJ22 -> 1645000 | AM22: Romb PPS Hari Sabtu-Minggu/Libur Nasional Anak | AN22: =AH22 -> 0
B23: Jumlah | C23: =SUM(C5:C22) -> 40430000 | D23: =SUM(D5:D22) -> 51673000 | E23: =SUM(E5:E22) -> 60021000 | F23: =SUM(F5:F22) -> 0 | G23: =SUM(G5:G22) -> 8747500 | H23: =SUM(H5:H22) -> 8153500 | I23: =SUM(I5:I22) -> 8313500 | J23: =SUM(J5:J22) -> 8069500 | ... AH23: =SUM(AH5:AH22) -> 737705000 | AJ23: =SUM(AJ5:AJ22) -> 634651000 | AM23: Jumlah | AN23: =AH23 -> 737705000
B27: PENGUNJUNG | AM27: ASURANSI LEMBAR
B28: T A N G G A L | C28: 1 | D28: 2 | E28: 3 | F28: 4 | G28: 5 | H28: 6 | I28: 7 | J28: 8 | K28: 9 | L28: 10 | M28: 11 | N28: 12 | O28: 13 | P28: 14 | Q28: 15 | R28: 16 | S28: 17 | T28: 18 | U28: 19 | V28: 20 | W28: 21 | X28: 22 | Y28: 23 | Z28: 24 | AA28: 25 | AB28: 26 | AC28: 27 | AD28: 28 | AE28: 29 | AF28: 30 | AG28: 31 | AH28: jumlah | AM28: T A N G G A L
B29: Dewasa | C29: =C5/4000 -> 6256 | D29: =D5/4000 -> 7520 | E29: =E5/4000 -> 8854 | F29: =F5/4000 -> 0 | G29: =G5/4000 -> 1747 | H29: =H5/4000 -> 1585 | I29: =I5/4000 -> 1593 | J29: =J5/4000 -> 1592 | ... AG29: =AG5/4000 -> 8637 | AH29: =SUM(C29:AG29) -> 114351 | AM29: Dewasa | AN29: =AH29 -> 114351
B30: Anak | C30: =C6/3000 -> 1882 | D30: =D6/3000 -> 2401 | E30: =E6/3000 -> 2635 | F30: =F6/3000 -> 0 | G30: =G6/3000 -> 342 | H30: =H6/3000 -> 324 | I30: =I6/3000 -> 354 | J30: =J6/3000 -> 353 | ... AG30: =AG6/3000 -> 2643 | AH30: =SUM(C30:AG30) -> 32494 | AM30: Anak | AN30: =AH30 -> 32494
B31: Rombongan Dewasa | C31: =C7/3000 -> 0 | D31: =D7/3000 -> 0 | E31: =E7/3000 -> 0 | F31: =F7/3000 -> 0 | G31: =G7/3000 -> 0 | H31: =H7/3000 -> 0 | I31: =I7/3000 -> 0 | J31: =J7/3000 -> 0 | ... AG31: =AG7/3000 -> 0 | AH31: =SUM(C31:AG31) -> 0 | AM31: Rombongan Dewasa | AN31: =AH31 -> 0
B32: Rombongan Anak | C32: =C8/2250 -> 0 | D32: =D8/2250 -> 0 | E32: =E8/2250 -> 0 | F32: =F8/2250 -> 0 | G32: =G8/2250 -> 0 | H32: =H8/2250 -> 0 | I32: =I8/2250 -> 0 | J32: =J8/2250 -> 0 | ... AG32: =AG8/2250 -> 0 | AH32: =SUM(C32:AG32) -> 0 | AM32: Rombongan Anak | AN32: =AH32 -> 0
B33: Taman Satwa Anak | C33: =C9/2500 -> 271 | D33: =D9/2500 -> 332 | E33: =E9/2500 -> 530 | F33: =F9/2500 -> 0 | G33: =G9/2500 -> 15 | H33: =H9/2500 -> 63 | I33: =I9/2500 -> 35 | J33: =J9/2500 -> 17 | ... AG33: =AG9/2500 -> 506 | AH33: =SUM(C33:AG33) -> 4916
B34: PPS Hari Selasa-Jum'at Dewasa | C34: =C10/6000 -> 0 | D34: =D10/6000 -> 0 | E34: =E10/6000 -> 0 | F34: =F10/6000 -> 0 | G34: =G10/6000 -> 70 | H34: =H10/6000 -> 66 | I34: =I10/6000 -> 83 | J34: =J10/6000 -> 65 | ... AG34: =AG10/6000 -> 0 | AH34: =SUM(C34:AG34) -> 817 | AM34: Sepeda | AN34: =AH34 -> 817
B35: PPS Hari Selasa-Jum'at Anak | C35: =C11/6000 -> 0 | D35: =D11/6000 -> 0 | E35: =E11/6000 -> 0 | F35: =F11/6000 -> 0 | G35: =G11/6000 -> 46 | H35: =H11/6000 -> 48 | I35: =I11/6000 -> 49 | J35: =J11/6000 -> 35 | ... AG35: =AG11/6000 -> 0 | AH35: =SUM(C35:AG35) -> 542 | AM35: JUMLAH Rp | AN35: =AH35 -> 542
B36: Romb PPS Hari Selasa-Jum'at Dewasa | C36: =C12/4500 -> 0 | D36: =D12/4500 -> 0 | E36: =E12/4500 -> 0 | F36: =F12/4500 -> 0 | G36: =G12/4500 -> 0 | H36: =H12/4500 -> 0 | I36: =I12/4500 -> 0 | J36: =J12/4500 -> 0 | ... AG36: =AG12/4500 -> 0 | AH36: =SUM(C36:AG36) -> 0 | AM36: PPS Dewasa | AN36: =AH36 -> 0
B37: Romb PPS Hari Selasa-Jum'at Anak | C37: =C13/4500 -> 0 | D37: =D13/4500 -> 0 | E37: =E13/4500 -> 0 | F37: =F13/4500 -> 0 | G37: =G13/4500 -> 0 | H37: =H13/4500 -> 0 | I37: =I13/4500 -> 0 | J37: =J13/4500 -> 0 | ... AG37: =AG13/4500 -> 0 | AH37: =SUM(C37:AG37) -> 0 | AM37: PPS Anak | AN37: =AH37 -> 0
B38: PPS Hari Sabtu-Minggu/Libur Nasional Dewasa | C38: =C14/7500 -> 717 | D38: =D14/7500 -> 1093 | E38: =E14/7500 -> 1202 | F38: =F14/7500 -> 0 | G38: =G14/7500 -> 0 | H38: =H14/7500 -> 0 | I38: =I14/7500 -> 0 | J38: =J14/7500 -> 0 | ... AG38: =AG14/7500 -> 1476 | AH38: =SUM(C38:AG38) -> 12784 | AM38: PPS Romb.Dewasa | AN38: =AH38 -> 12784
B39: PPS Hari Sabtu-Minggu/Libur Nasional Anak | C39: =C15/7500 -> 494 | D39: =D15/7500 -> 715 | E39: =E15/7500 -> 848 | F39: =F15/7500 -> 0 | G39: =G15/7500 -> 0 | H39: =H15/7500 -> 0 | I39: =I15/7500 -> 0 | J39: =J15/7500 -> 0 | ... AG39: =AG15/7500 -> 975 | AH39: =SUM(C39:AG39) -> 8866 | AM39: PPS Romb. Anak | AN39: =AH39 -> 8866
B40: Romb PPS Hari Sabtu-Minggu/Libur Nasional Dewasa | C40: =C16/5625 -> 0 | D40: =D16/5625 -> 0 | E40: =E16/5625 -> 0 | F40: =F16/5625 -> 0 | G40: =G16/5625 -> 0 | H40: =H16/5625 -> 0 | I40: =I16/5625 -> 0 | J40: =J16/5625 -> 0 | ... AG40: =AG16/5625 -> #VALUE! | AH40: =SUM(C40:AG40) -> #VALUE! | AM40: JUMLAH Rp | AN40: =AH40 -> #VALUE!
B41: Romb PPS Hari Sabtu-Minggu/Libur Nasional Anak | C41: =C17/5625 -> 0 | D41: =D17/5625 -> 0 | E41: =E17/5625 -> 0 | F41: =F17/5625 -> 0 | G41: =G17/5625 -> 0 | H41: =H17/5625 -> 0 | I41: =I17/5625 -> 0 | J41: =J17/5625 -> 0 | ... AG41: =AG17/5625 -> 0 | AH41: =SUM(C41:AG41) -> 0
B42: Kendaraan Golongan I | C42: =C18/15000 -> 0 | D42: =D18/15000 -> 0 | E42: =E18/15000 -> 0 | F42: =F18/15000 -> 0 | G42: =G18/15000 -> 0 | H42: =H18/15000 -> 0 | I42: =I18/15000 -> 0 | J42: =J18/15000 -> 0 | ... AG42: =AG18/15000 -> 0 | AH42: =SUM(C42:AG42) -> 0
B43: Kendaraan Golongan II | C43: =C19/12500 -> 0 | D43: =D19/12500 -> 0 | E43: =E19/12500 -> 0 | F43: =F19/12500 -> 0 | G43: =G19/12500 -> 0 | H43: =H19/12500 -> 0 | I43: =I19/12500 -> 0 | J43: =J19/12500 -> 0 | ... AG43: =AG19/12500 -> 0 | AH43: =SUM(C43:AG43) -> 0
B44: Kendaraan Golongan III | C44: =C20/6000 -> 0 | D44: =D20/6000 -> 0 | E44: =E20/6000 -> 0 | F44: =F20/6000 -> 0 | G44: =G20/6000 -> 0 | H44: =H20/6000 -> 0 | I44: =I20/6000 -> 0 | J44: =J20/6000 -> 0 | ... AG44: =AG20/6000 -> 0 | AH44: =SUM(C44:AG44) -> 0
...

Sheet JUNI IRMA
A1: DATA RINCIAN PENDAPATAN E-TICKETING NEW GATE BULAN JUNI 2026
A3: NO | B3: JENIS PENDAPATAN | C3: TANGGAL | AG3: JUMLAH | AL3: PENDAPATAN
C4: 1 | D4: 2 | E4: 3 | F4: 4 | G4: 5 | H4: 6 | I4: 7 | J4: 8 | K4: 9 | L4: 10 | M4: 11 | N4: 12 | O4: 13 | P4: 14 | Q4: 15 | R4: 16 | S4: 17 | T4: 18 | U4: 19 | V4: 20 | W4: 21 | X4: 22 | Y4: 23 | Z4: 24 | AA4: 25 | AB4: 26 | AC4: 27 | AD4: 28 | AE4: 29 | AF4: 30 | AL4: TAMAN MARGASATWA RAGUNAN 2018 :
A5: 1 | B5: Dewasa | C5: 19900000 | E5: 6672000 | F5: 4960000 | G5: 4308000 | H5: 16712000 | I5: 27216000 | K5: 6104000 | L5: 6720000 | M5: 5368000 | N5: 5328000 | O5: 22112000 | P5: 25836000 | R5: 23164000 | S5: 6916000 | T5: 6200000 | U5: 6160000 | V5: 21584000 | W5: 31436000 | Y5: 13992000 | Z5: 11500000 | AA5: 11832000 | AB5: 13868000 | AG5: =SUM(C5:AF5) -> 297888000 | AH5: =AG5/4000 -> 74472 | AI5: 284764000 | AJ5: =AG5+AI5 -> 582652000 | AL5: Dewasa | AM5: =AG5 -> 297888000
A6: 2 | B6: Anak | C6: 4572000 | E6: 1221000 | F6: 795000 | G6: 795000 | H6: 3177000 | I6: 5313000 | K6: 1389000 | L6: 1212000 | M6: 912000 | N6: 873000 | O6: 4287000 | P6: 5958000 | R6: 5046000 | S6: 1674000 | T6: 1800000 | U6: 1212000 | V6: 4728000 | W6: 8307000 | Y6: 4617000 | Z6: 3699000 | AA6: 4152000 | AB6: 3585000 | AG6: =SUM(C6:AF6) -> 69324000 | AH6: =AG6/3000 -> 23108 | AI6: 46983000 | AJ6: =AG6+AI6 -> 116307000 | AL6: Anak | AM6: =AG6 -> 69324000
A7: 3 | B7: Rombongan Dewasa | AG7: =SUM(C7:AF7) -> 0 | AH7: =AG7/3000 -> 0 | AJ7: =AG7+AI7 -> 0 | AL7: Rombongan Dewasa | AM7: =AG7 -> 0
A8: 4 | B8: Rombongan Anak | AG8: =SUM(C8:AF8) -> 0 | AH8: =AG8/2250 -> 0 | AJ8: =AG8+AI8 -> 0 | AL8: Rombongan Anak | AM8: =AG8 -> 0
A9: 5 | B9: Taman Satwa Anak | C9: 797500 | E9: 50000 | F9: 62500 | G9: 30000 | H9: 422500 | I9: 717500 | K9: 55000 | L9: 187500 | M9: 77500 | N9: 67500 | O9: 405000 | P9: 850000 | R9: 602500 | S9: 45000 | T9: 37500 | U9: 42500 | V9: 377500 | W9: 1067500 | X9: 275000 | Y9: 52500 | Z9: 77500 | AA9: 167500 | AB9: 112500 | AC9: 1020000 | AD9: 1605000 | AG9: =SUM(C9:AF9) -> 9205000 | AH9: =AG9/2500 -> 3682 | AI9: 36635000 | AJ9: =AG9+AI9 -> 45840000
A10: 6 | B10: PPS Hari Selasa-Jum'at Dewasa | E10: 1044000 | F10: 660000 | G10: 474000 | K10: 888000 | L10: 1614000 | M10: 1380000 | N10: 840000 | S10: 1104000 | T10: 1512000 | U10: 948000 | X10: 894000 | Y10: 1632000 | Z10: 2256000 | AA10: 2262000 | AB10: 2448000 | AG10: =SUM(C10:AF10) -> 19956000 | AH10: =AG10/6000 -> 3326 | AI10: 54252000 | AJ10: =AG10+AI10 -> 74208000 | AL10: Sepeda | AM10: =AG10 -> 19956000
A11: 7 | B11: PPS Hari Selasa-Jum'at Anak | E11: 246000 | F11: 492000 | G11: 264000 | K11: 708000 | L11: 768000 | M11: 816000 | N11: 606000 | S11: 732000 | T11: 1050000 | U11: 540000 | X11: 576000 | Y11: 870000 | Z11: 1374000 | AA11: 1200000 | AB11: 1746000 | AG11: =SUM(C11:AF11) -> 11988000 | AH11: =AG11/6000 -> 1998 | AI11: 13356000 | AJ11: =AG11+AI11 -> 25344000 | AL11: Kuda Tunggang | AM11: =AG11 -> 11988000
A12: 8 | B12: Romb PPS Hari Selasa-Jum'at Dewasa | AG12: =SUM(C12:AF12) -> 0 | AH12: =AG12/4500 -> 0 | AJ12: =AG12+AI12 -> 0 | AL12: Unta Tunggang | AM12: =AG12 -> 0
A13: 9 | B13: Romb PPS Hari Selasa-Jum'at Anak | AG13: =SUM(C13:AF13) -> 0 | AH13: =AG13/4500 -> 0 | AJ13: =AG13+AI13 -> 0 | AL13: Gajah Tunggang | AM13: =AG13 -> 0
A14: 10 | B14: PPS Hari Sabtu-Minggu/Libur Nasional Dewasa | C14: 6277500 | H14: 4687500 | I14: 8115000 | O14: 4702500 | P14: 6442500 | R14: 9817500 | V14: 4957500 | W14: 9630000 | AC14: 12697500 | AD14: 18202500 | AG14: =SUM(C14:AF14) -> 85530000 | AH14: =AG14/7500 -> 11404 | AI14: 111577500 | AJ14: =AG14+AI14 -> 197107500 | AL14: Taman Satwa Anak / Pentas | AM14: =AG14 -> 85530000
A15: 11 | B15: PPS Hari Sabtu-Minggu/Libur Nasional Anak | C15: 4635000 | H15: 3360000 | I15: 5730000 | O15: 3157500 | P15: 4327500 | R15: 6525000 | V15: 3742500 | W15: 6405000 | AC15: 9382500 | AD15: 14332500 | AG15: =SUM(C15:AF15) -> 61597500 | AH15: =AG15/7500 -> 8213 | AI15: 25185000 | AJ15: =AG15+AI15 -> 86782500 | AL15: PPS Hari Selasa-Jum'at Dewasa | AM15: =AG15 -> 61597500
A16: 12 | B16: Romb PPS Hari Sabtu-Minggu/Libur Nasional Dewasa | AG16: =SUM(C16:AF16) -> 0 | AH16: =AG16/5625 -> 0 | AJ16: =AG16+AI16 -> 0 | AL16: PPS Hari Selasa-Jum'at Anak | AM16: =AG16 -> 0
A17: 13 | B17: Romb PPS Hari Sabtu-Minggu/Libur Nasional Anak | AG17: =SUM(C17:AF17) -> 0 | AH17: =AG17/5625 -> 0 | AJ17: =AG17+AI17 -> 0 | AL17: Romb PPS Hari Selasa-Jum'at Dewasa | AM17: =AG17 -> 0
